Workbook

Sheet About
B2: Nebraska Football Win History (1890-2025)
B3: Drew White - Data Visualization Project
B5: Dataset | C5: Nebraska Cornhuskers football season-by-season results, 1890-2025 (136 completed seasons).
B6: Source | C6: Wikipedia, 'List of Nebraska Cornhuskers football seasons' (https://en.wikipedia.org/wiki/List_of_Nebraska_Cornhuskers_football_seasons), retrieved Oct 9, 2026; table compiled from the Nebraska Athletics Football Record Book and NCAA records.
B7: Raw_Data | C7: The table as retrieved: 137 rows x 9 columns, text values (records like '9–2–1', ranks like 'T–20').
B8: Clean_Data | C8: Cleaned table used for all charts: 136 rows x 25 columns of numeric and categorical fields.
B9: Cleaning_Log | C9: Every cleaning step applied to get from Raw_Data to Clean_Data.
B10: G1 - G6 | C10: One sheet per goal: a formula-driven summary table, the chart, and the story for that goal.
B12: Project goals
B13: G1_Trend | C13: Show how Nebraska's win percentage has changed from 1890 to 2025.
B14: G2_Decades | C14: Compare win percentage by decade to find the best and worst decades.
B15: G3_Coaches | C15: Compare the win percentage of every head coach since 1962.
B16: G4_Eras | C16: Compare Nebraska's results in the Big Eight, Big 12, and Big Ten.
B17: G5_Bowls | C17: Show bowl wins and losses by decade.
B18: G6_Rankings | C18: Show Nebraska's final AP ranking each season to see when they were a national power.

Sheet Raw_Data
A1: Year | B1: Coach | C1: Conference_Name | D1: Overall | E1: Conference | F1: Standing | G1: Bowl/playoffs | H1: Coaches | I1: AP
A2: 1890 | B2: Langdon Frothingham | C2: Independent | D2: 2–0
A3: 1891 | B3: Theron Lyman | C3: Independent | D3: 2–2
A4: 1892 | B4: J. S. Williams | C4: WIUFA | D4: 2–2–1 | E4: 1–1–1 | F4: 2nd
A5: 1893 | B5: Frank Crawford | C5: WIUFA | D5: 3–2–1 | E5: 1–2 | F5: 3rd
A6: 1894 | B6: Frank Crawford | C6: WIUFA | D6: 6–2 | E6: 2–1 | F6: 1st
A7: 1895 | B7: Charles Thomas | C7: WIUFA | D7: 6–3 | E7: 2–1 | F7: T–1st
A8: 1896 | B8: Edward N. Robinson | C8: WIUFA | D8: 6–3–1 | E8: 1–1–1 | F8: 3rd
A9: 1897 | B9: Edward N. Robinson | C9: WIUFA | D9: 5–1 | E9: 3–0 | F9: 1st
A10: 1898 | B10: Fielding H. Yost | C10: Independent | D10: 8–3
A11: 1899 | B11: Alonzo Edwin Branch | C11: Independent | D11: 1–7–1
A12: 1900 | B12: Walter C. Booth | C12: Independent | D12: 6–1–1
A13: 1901 | B13: Walter C. Booth | C13: Independent | D13: 6–2
A14: 1902 | B14: Walter C. Booth | C14: Independent | D14: 9–0
A15: 1903 | B15: Walter C. Booth | C15: Independent | D15: 10–0
A16: 1904 | B16: Walter C. Booth | C16: Independent | D16: 7–3
A17: 1905 | B17: Walter C. Booth | C17: Independent | D17: 8–2
A18: 1906 | B18: Amos Foster | C18: Independent | D18: 6–4
A19: 1907 | B19: William C. Cole | C19: MVIAA | D19: 8–2 | E19: 1–0 | F19: T–1st
A20: 1908 | B20: William C. Cole | C20: MVIAA | D20: 7–2–1 | E20: 2–1 | F20: T–2nd
A21: 1909 | B21: William C. Cole | C21: MVIAA | D21: 3–3–2 | E21: 0–2–1 | F21: T–5th
A22: 1910 | B22: William C. Cole | C22: MVIAA | D22: 7–1 | E22: 2–0 | F22: 1st
A23: 1911 | B23: Ewald O. Stiehm | C23: MVIAA | D23: 5–1–2 | E23: 2–0–1 | F23: T–1st
A24: 1912 | B24: Ewald O. Stiehm | C24: MVIAA | D24: 7–1 | E24: 2–0 | F24: T–1st
A25: 1913 | B25: Ewald O. Stiehm | C25: MVIAA | D25: 8–0 | E25: 3–0 | F25: T–1st
A26: 1914 | B26: Ewald O. Stiehm | C26: MVIAA | D26: 7–0–1 | E26: 3–0 | F26: 1st
A27: 1915 | B27: Ewald O. Stiehm | C27: MVIAA | D27: 8–0 | E27: 4–0 | F27: 1st
A28: 1916 | B28: E. J. Stewart | C28: MVIAA | D28: 6–2 | E28: 3–1 | F28: 1st
A29: 1917 | B29: E. J. Stewart | C29: MVIAA | D29: 5–2 | E29: 2–0 | F29: 1st
A30: 1918 | B30: William G. Kline | C30: MVIAA | D30: 2–3–1 | E30: 0–0
A31: 1919 | B31: Henry Schulte | C31: Independent | D31: 3–3–2
A32: 1920 | B32: Henry Schulte | C32: Independent | D32: 5–3–1
A33: 1921 | B33: Fred Dawson | C33: MVIAA | D33: 7–1 | E33: 3–0 | F33: 1st
A34: 1922 | B34: Fred Dawson | C34: MVIAA | D34: 7–1 | E34: 5–0 | F34: 1st
A35: 1923 | B35: Fred Dawson | C35: MVIAA | D35: 4–2–2 | E35: 3–0–2 | F35: 1st
A36: 1924 | B36: Fred Dawson | C36: MVIAA | D36: 5–3 | E36: 3–1 | F36: 2nd
A37: 1925 | B37: Ernest Bearg | C37: MVIAA | D37: 4–2–2 | E37: 2–2–1 | F37: 5th
A38: 1926 | B38: Ernest Bearg | C38: MVIAA | D38: 6–2 | E38: 5–1 | F38: 2nd
A39: 1927 | B39: Ernest Bearg | C39: MVIAA | D39: 6–2 | E39: 4–1 | F39: 2nd
A40: 1928 | B40: Ernest Bearg | C40: MVIAA | D40: 7–1–1 | E40: 5–0 | F40: 1st
...

Sheet Clean_Data
A1: Season | B1: Decade | C1: Head_Coach | D1: Conference | E1: Conference_Era | F1: Wins | G1: Losses | H1: Ties | I1: Games | J1: Win_Pct | K1: Conf_Wins | L1: Conf_Losses | M1: Conf_Ties | N1: Conf_Win_Pct | O1: Conf_Finish | P1: Finish_Tied | Q1: Division | R1: Bowl_Game | S1: Bowl_Name | T1: Bowl_Result | U1: Major_Bowl | V1: AP_Final_Rank | W1: Coaches_Final_Rank | X1: AP_Ranked | Y1: Winning_Season
A2: 1890 | B2: 1890s | C2: Langdon Frothingham | D2: Independent | E2: Independent | F2: 2 | G2: 0 | H2: 0 | I2: 2 | J2: 1 | R2: No | U2: No | X2: No | Y2: Yes
A3: 1891 | B3: 1890s | C3: Theron Lyman | D3: Independent | E3: Independent | F3: 2 | G3: 2 | H3: 0 | I3: 4 | J3: 0.5 | R3: No | U3: No | X3: No | Y3: No
A4: 1892 | B4: 1890s | C4: J. S. Williams | D4: WIUFA | E4: WIUFA (1892-97) | F4: 2 | G4: 2 | H4: 1 | I4: 5 | J4: 0.5 | K4: 1 | L4: 1 | M4: 1 | N4: 0.5 | O4: 2 | P4: No | R4: No | U4: No | X4: No | Y4: No
A5: 1893 | B5: 1890s | C5: Frank Crawford | D5: WIUFA | E5: WIUFA (1892-97) | F5: 3 | G5: 2 | H5: 1 | I5: 6 | J5: 0.5833 | K5: 1 | L5: 2 | M5: 0 | N5: 0.3333 | O5: 3 | P5: No | R5: No | U5: No | X5: No | Y5: Yes
A6: 1894 | B6: 1890s | C6: Frank Crawford | D6: WIUFA | E6: WIUFA (1892-97) | F6: 6 | G6: 2 | H6: 0 | I6: 8 | J6: 0.75 | K6: 2 | L6: 1 | M6: 0 | N6: 0.6667 | O6: 1 | P6: No | R6: No | U6: No | X6: No | Y6: Yes
A7: 1895 | B7: 1890s | C7: Charles Thomas | D7: WIUFA | E7: WIUFA (1892-97) | F7: 6 | G7: 3 | H7: 0 | I7: 9 | J7: 0.6667 | K7: 2 | L7: 1 | M7: 0 | N7: 0.6667 | O7: 1 | P7: Yes | R7: No | U7: No | X7: No | Y7: Yes
A8: 1896 | B8: 1890s | C8: Edward N. Robinson | D8: WIUFA | E8: WIUFA (1892-97) | F8: 6 | G8: 3 | H8: 1 | I8: 10 | J8: 0.65 | K8: 1 | L8: 1 | M8: 1 | N8: 0.5 | O8: 3 | P8: No | R8: No | U8: No | X8: No | Y8: Yes
A9: 1897 | B9: 1890s | C9: Edward N. Robinson | D9: WIUFA | E9: WIUFA (1892-97) | F9: 5 | G9: 1 | H9: 0 | I9: 6 | J9: 0.8333 | K9: 3 | L9: 0 | M9: 0 | N9: 1 | O9: 1 | P9: No | R9: No | U9: No | X9: No | Y9: Yes
A10: 1898 | B10: 1890s | C10: Fielding H. Yost | D10: Independent | E10: Independent | F10: 8 | G10: 3 | H10: 0 | I10: 11 | J10: 0.7273 | R10: No | U10: No | X10: No | Y10: Yes
A11: 1899 | B11: 1890s | C11: Alonzo Edwin Branch | D11: Independent | E11: Independent | F11: 1 | G11: 7 | H11: 1 | I11: 9 | J11: 0.1667 | R11: No | U11: No | X11: No | Y11: No
A12: 1900 | B12: 1900s | C12: Walter C. Booth | D12: Independent | E12: Independent | F12: 6 | G12: 1 | H12: 1 | I12: 8 | J12: 0.8125 | R12: No | U12: No | X12: No | Y12: Yes
A13: 1901 | B13: 1900s | C13: Walter C. Booth | D13: Independent | E13: Independent | F13: 6 | G13: 2 | H13: 0 | I13: 8 | J13: 0.75 | R13: No | U13: No | X13: No | Y13: Yes
A14: 1902 | B14: 1900s | C14: Walter C. Booth | D14: Independent | E14: Independent | F14: 9 | G14: 0 | H14: 0 | I14: 9 | J14: 1 | R14: No | U14: No | X14: No | Y14: Yes
A15: 1903 | B15: 1900s | C15: Walter C. Booth | D15: Independent | E15: Independent | F15: 10 | G15: 0 | H15: 0 | I15: 10 | J15: 1 | R15: No | U15: No | X15: No | Y15: Yes
A16: 1904 | B16: 1900s | C16: Walter C. Booth | D16: Independent | E16: Independent | F16: 7 | G16: 3 | H16: 0 | I16: 10 | J16: 0.7 | R16: No | U16: No | X16: No | Y16: Yes
A17: 1905 | B17: 1900s | C17: Walter C. Booth | D17: Independent | E17: Independent | F17: 8 | G17: 2 | H17: 0 | I17: 10 | J17: 0.8 | R17: No | U17: No | X17: No | Y17: Yes
A18: 1906 | B18: 1900s | C18: Amos Foster | D18: Independent | E18: Independent | F18: 6 | G18: 4 | H18: 0 | I18: 10 | J18: 0.6 | R18: No | U18: No | X18: No | Y18: Yes
A19: 1907 | B19: 1900s | C19: William C. Cole | D19: MVIAA | E19: MVIAA / Big Six-Seven (1907-61) | F19: 8 | G19: 2 | H19: 0 | I19: 10 | J19: 0.8 | K19: 1 | L19: 0 | M19: 0 | N19: 1 | O19: 1 | P19: Yes | R19: No | U19: No | X19: No | Y19: Yes
A20: 1908 | B20: 1900s | C20: William C. Cole | D20: MVIAA | E20: MVIAA / Big Six-Seven (1907-61) | F20: 7 | G20: 2 | H20: 1 | I20: 10 | J20: 0.75 | K20: 2 | L20: 1 | M20: 0 | N20: 0.6667 | O20: 2 | P20: Yes | R20: No | U20: No | X20: No | Y20: Yes
A21: 1909 | B21: 1900s | C21: William C. Cole | D21: MVIAA | E21: MVIAA / Big Six-Seven (1907-61) | F21: 3 | G21: 3 | H21: 2 | I21: 8 | J21: 0.5 | K21: 0 | L21: 2 | M21: 1 | N21: 0.1667 | O21: 5 | P21: Yes | R21: No | U21: No | X21: No | Y21: No
A22: 1910 | B22: 1910s | C22: William C. Cole | D22: MVIAA | E22: MVIAA / Big Six-Seven (1907-61) | F22: 7 | G22: 1 | H22: 0 | I22: 8 | J22: 0.875 | K22: 2 | L22: 0 | M22: 0 | N22: 1 | O22: 1 | P22: No | R22: No | U22: No | X22: No | Y22: Yes
A23: 1911 | B23: 1910s | C23: Ewald O. Stiehm | D23: MVIAA | E23: MVIAA / Big Six-Seven (1907-61) | F23: 5 | G23: 1 | H23: 2 | I23: 8 | J23: 0.75 | K23: 2 | L23: 0 | M23: 1 | N23: 0.8333 | O23: 1 | P23: Yes | R23: No | U23: No | X23: No | Y23: Yes
A24: 1912 | B24: 1910s | C24: Ewald O. Stiehm | D24: MVIAA | E24: MVIAA / Big Six-Seven (1907-61) | F24: 7 | G24: 1 | H24: 0 | I24: 8 | J24: 0.875 | K24: 2 | L24: 0 | M24: 0 | N24: 1 | O24: 1 | P24: Yes | R24: No | U24: No | X24: No | Y24: Yes
A25: 1913 | B25: 1910s | C25: Ewald O. Stiehm | D25: MVIAA | E25: MVIAA / Big Six-Seven (1907-61) | F25: 8 | G25: 0 | H25: 0 | I25: 8 | J25: 1 | K25: 3 | L25: 0 | M25: 0 | N25: 1 | O25: 1 | P25: Yes | R25: No | U25: No | X25: No | Y25: Yes
A26: 1914 | B26: 1910s | C26: Ewald O. Stiehm | D26: MVIAA | E26: MVIAA / Big Six-Seven (1907-61) | F26: 7 | G26: 0 | H26: 1 | I26: 8 | J26: 0.9375 | K26: 3 | L26: 0 | M26: 0 | N26: 1 | O26: 1 | P26: No | R26: No | U26: No | X26: No | Y26: Yes
A27: 1915 | B27: 1910s | C27: Ewald O. Stiehm | D27: MVIAA | E27: MVIAA / Big Six-Seven (1907-61) | F27: 8 | G27: 0 | H27: 0 | I27: 8 | J27: 1 | K27: 4 | L27: 0 | M27: 0 | N27: 1 | O27: 1 | P27: No | R27: No | U27: No | X27: No | Y27: Yes
A28: 1916 | B28: 1910s | C28: E. J. Stewart | D28: MVIAA | E28: MVIAA / Big Six-Seven (1907-61) | F28: 6 | G28: 2 | H28: 0 | I28: 8 | J28: 0.75 | K28: 3 | L28: 1 | M28: 0 | N28: 0.75 | O28: 1 | P28: No | R28: No | U28: No | X28: No | Y28: Yes
A29: 1917 | B29: 1910s | C29: E. J. Stewart | D29: MVIAA | E29: MVIAA / Big Six-Seven (1907-61) | F29: 5 | G29: 2 | H29: 0 | I29: 7 | J29: 0.7143 | K29: 2 | L29: 0 | M29: 0 | N29: 1 | O29: 1 | P29: No | R29: No | U29: No | X29: No | Y29: Yes
A30: 1918 | B30: 1910s | C30: William G. Kline | D30: MVIAA | E30: MVIAA / Big Six-Seven (1907-61) | F30: 2 | G30: 3 | H30: 1 | I30: 6 | J30: 0.4167 | R30: No | U30: No | X30: No | Y30: No
A31: 1919 | B31: 1910s | C31: Henry Schulte | D31: Independent | E31: Independent | F31: 3 | G31: 3 | H31: 2 | I31: 8 | J31: 0.5 | R31: No | U31: No | X31: No | Y31: No
A32: 1920 | B32: 1920s | C32: Henry Schulte | D32: Independent | E32: Independent | F32: 5 | G32: 3 | H32: 1 | I32: 9 | J32: 0.6111 | R32: No | U32: No | X32: No | Y32: Yes
A33: 1921 | B33: 1920s | C33: Fred Dawson | D33: MVIAA | E33: MVIAA / Big Six-Seven (1907-61) | F33: 7 | G33: 1 | H33: 0 | I33: 8 | J33: 0.875 | K33: 3 | L33: 0 | M33: 0 | N33: 1 | O33: 1 | P33: No | R33: No | U33: No | X33: No | Y33: Yes
A34: 1922 | B34: 1920s | C34: Fred Dawson | D34: MVIAA | E34: MVIAA / Big Six-Seven (1907-61) | F34: 7 | G34: 1 | H34: 0 | I34: 8 | J34: 0.875 | K34: 5 | L34: 0 | M34: 0 | N34: 1 | O34: 1 | P34: No | R34: No | U34: No | X34: No | Y34: Yes
A35: 1923 | B35: 1920s | C35: Fred Dawson | D35: MVIAA | E35: MVIAA / Big Six-Seven (1907-61) | F35: 4 | G35: 2 | H35: 2 | I35: 8 | J35: 0.625 | K35: 3 | L35: 0 | M35: 2 | N35: 0.8 | O35: 1 | P35: No | R35: No | U35: No | X35: No | Y35: Yes
A36: 1924 | B36: 1920s | C36: Fred Dawson | D36: MVIAA | E36: MVIAA / Big Six-Seven (1907-61) | F36: 5 | G36: 3 | H36: 0 | I36: 8 | J36: 0.625 | K36: 3 | L36: 1 | M36: 0 | N36: 0.75 | O36: 2 | P36: No | R36: No | U36: No | X36: No | Y36: Yes
A37: 1925 | B37: 1920s | C37: Ernest Bearg | D37: MVIAA | E37: MVIAA / Big Six-Seven (1907-61) | F37: 4 | G37: 2 | H37: 2 | I37: 8 | J37: 0.625 | K37: 2 | L37: 2 | M37: 1 | N37: 0.5 | O37: 5 | P37: No | R37: No | U37: No | X37: No | Y37: Yes
A38: 1926 | B38: 1920s | C38: Ernest Bearg | D38: MVIAA | E38: MVIAA / Big Six-Seven (1907-61) | F38: 6 | G38: 2 | H38: 0 | I38: 8 | J38: 0.75 | K38: 5 | L38: 1 | M38: 0 | N38: 0.8333 | O38: 2 | P38: No | R38: No | U38: No | X38: No | Y38: Yes
A39: 1927 | B39: 1920s | C39: Ernest Bearg | D39: MVIAA | E39: MVIAA / Big Six-Seven (1907-61) | F39: 6 | G39: 2 | H39: 0 | I39: 8 | J39: 0.75 | K39: 4 | L39: 1 | M39: 0 | N39: 0.8 | O39: 2 | P39: No | R39: No | U39: No | X39: No | Y39: Yes
A40: 1928 | B40: 1920s | C40: Ernest Bearg | D40: MVIAA | E40: MVIAA / Big Six-Seven (1907-61) | F40: 7 | G40: 1 | H40: 1 | I40: 9 | J40: 0.8333 | K40: 5 | L40: 0 | M40: 0 | N40: 1 | O40: 1 | P40: No | R40: No | U40: No | X40: No | Y40: Yes
...

Sheet Cleaning_Log
A1: Step | B1: Cleaning action
A2: 1 | B2: Removed 2026 (season in progress, 2-0 at time of pull): 137 -> 136 rows
A3: 2 | B3: Split W-L-T strings into numeric Wins, Losses, Ties (en dash separators normalized)
A4: 3 | B4: Computed Win_Pct and Conf_Win_Pct with ties counted as half a win
A5: 4 | B5: 1918 conference record 0-0 (no MVIAA champion; WWI/flu) set to blank
A6: 5 | B6: Stripped † BCS/Bowl Alliance markers from bowl names; split bowl into Name + W/L result
A7: 6 | B7: Rankings: removed 'T-' tie prefix, converted to integers; unranked = blank
A8: 7 | B8: Standing: split into numeric finish, tie flag, and division (North/Legends/West)
A9: 8 | B9: Merged 'MVIAA / Big Eight' label into Big Eight; added Conference_Era and Decade groupings
A10: 9 | B10: Conference name was carried down from the source table's coach/conference section headers into its own Conference_Name column during collection
A11: 10 | B11: Result: 9 raw text columns -> 25 typed analysis columns (numeric records, percentages, flags, groupings)
A12: 11 | B12: Validation: cleaned totals 931-436-40 match the source all-time record (933-436-40) minus the 2-0 partial 2026 season

Sheet G1_Trend
A1: Goal 1: Win % Over Time
A2: Goal: Show how Nebraska's win percentage has changed from 1890 to 2025.
L4: Season | M4: Win % | N4: 10-Season Avg
L5: =Clean_Data!A2 -> 1890 | M5: =Clean_Data!J2 -> 1
L6: =Clean_Data!A3 -> 1891 | M6: =Clean_Data!J3 -> 0.5
L7: =Clean_Data!A4 -> 1892 | M7: =Clean_Data!J4 -> 0.5
L8: =Clean_Data!A5 -> 1893 | M8: =Clean_Data!J5 -> 0.5833
L9: =Clean_Data!A6 -> 1894 | M9: =Clean_Data!J6 -> 0.75
L10: =Clean_Data!A7 -> 1895 | M10: =Clean_Data!J7 -> 0.6667
L11: =Clean_Data!A8 -> 1896 | M11: =Clean_Data!J8 -> 0.65
L12: =Clean_Data!A9 -> 1897 | M12: =Clean_Data!J9 -> 0.8333
L13: =Clean_Data!A10 -> 1898 | M13: =Clean_Data!J10 -> 0.7273
L14: =Clean_Data!A11 -> 1899 | M14: =Clean_Data!J11 -> 0.1667 | N14: =AVERAGE(M5:M14) -> 0.63773
L15: =Clean_Data!A12 -> 1900 | M15: =Clean_Data!J12 -> 0.8125 | N15: =AVERAGE(M6:M15) -> 0.61898
L16: =Clean_Data!A13 -> 1901 | M16: =Clean_Data!J13 -> 0.75 | N16: =AVERAGE(M7:M16) -> 0.64398
L17: =Clean_Data!A14 -> 1902 | M17: =Clean_Data!J14 -> 1 | N17: =AVERAGE(M8:M17) -> 0.69398
L18: =Clean_Data!A15 -> 1903 | M18: =Clean_Data!J15 -> 1 | N18: =AVERAGE(M9:M18) -> 0.73565
L19: =Clean_Data!A16 -> 1904 | M19: =Clean_Data!J16 -> 0.7 | N19: =AVERAGE(M10:M19) -> 0.73065
L20: =Clean_Data!A17 -> 1905 | M20: =Clean_Data!J17 -> 0.8 | N20: =AVERAGE(M11:M20) -> 0.74398
L21: =Clean_Data!A18 -> 1906 | M21: =Clean_Data!J18 -> 0.6 | N21: =AVERAGE(M12:M21) -> 0.73898
L22: =Clean_Data!A19 -> 1907 | M22: =Clean_Data!J19 -> 0.8 | N22: =AVERAGE(M13:M22) -> 0.73565
L23: =Clean_Data!A20 -> 1908 | M23: =Clean_Data!J20 -> 0.75 | N23: =AVERAGE(M14:M23) -> 0.73792
L24: =Clean_Data!A21 -> 1909 | M24: =Clean_Data!J21 -> 0.5 | N24: =AVERAGE(M15:M24) -> 0.77125
L25: =Clean_Data!A22 -> 1910 | M25: =Clean_Data!J22 -> 0.875 | N25: =AVERAGE(M16:M25) -> 0.7775
A26: Story | L26: =Clean_Data!A23 -> 1911 | M26: =Clean_Data!J23 -> 0.75 | N26: =AVERAGE(M17:M26) -> 0.7775
A27: The 10-season average shows three big periods. Nebraska won a lot early on, then hit its low point in the 1940s and 50s (.337 average by 1951). After Bob Devaney was hired in 1962 the line shot up and peaked at .881 from 1992-2001. Since then it has gone down, and the 2016-2025 average (.423) is the lowest since 1962. | L27: =Clean_Data!A24 -> 1912 | M27: =Clean_Data!J24 -> 0.875 | N27: =AVERAGE(M18:M27) -> 0.765
L28: =Clean_Data!A25 -> 1913 | M28: =Clean_Data!J25 -> 1 | N28: =AVERAGE(M19:M28) -> 0.765
L29: =Clean_Data!A26 -> 1914 | M29: =Clean_Data!J26 -> 0.9375 | N29: =AVERAGE(M20:M29) -> 0.78875
L30: =Clean_Data!A27 -> 1915 | M30: =Clean_Data!J27 -> 1 | N30: =AVERAGE(M21:M30) -> 0.80875
L31: =Clean_Data!A28 -> 1916 | M31: =Clean_Data!J28 -> 0.75 | N31: =AVERAGE(M22:M31) -> 0.82375
L32: =Clean_Data!A29 -> 1917 | M32: =Clean_Data!J29 -> 0.7143 | N32: =AVERAGE(M23:M32) -> 0.81518
L33: =Clean_Data!A30 -> 1918 | M33: =Clean_Data!J30 -> 0.4167 | N33: =AVERAGE(M24:M33) -> 0.78185
L34: =Clean_Data!A31 -> 1919 | M34: =Clean_Data!J31 -> 0.5 | N34: =AVERAGE(M25:M34) -> 0.78185
L35: =Clean_Data!A32 -> 1920 | M35: =Clean_Data!J32 -> 0.6111 | N35: =AVERAGE(M26:M35) -> 0.75546
L36: =Clean_Data!A33 -> 1921 | M36: =Clean_Data!J33 -> 0.875 | N36: =AVERAGE(M27:M36) -> 0.76796
L37: =Clean_Data!A34 -> 1922 | M37: =Clean_Data!J34 -> 0.875 | N37: =AVERAGE(M28:M37) -> 0.76796
L38: =Clean_Data!A35 -> 1923 | M38: =Clean_Data!J35 -> 0.625 | N38: =AVERAGE(M29:M38) -> 0.73046
L39: =Clean_Data!A36 -> 1924 | M39: =Clean_Data!J36 -> 0.625 | N39: =AVERAGE(M30:M39) -> 0.69921
... L140: =Clean_Data!A137 -> 2025 | M140: =Clean_Data!J137 -> 0.5385 | N140: =AVERAGE(M131:M140) -> 0.42276

Sheet G2_Decades
A1: Goal 2: Win % by Decade
A2: Goal: Compare win percentage by decade to find the best and worst decades.
L4: Decade | M4: Seasons | N4: Wins | O4: Losses | P4: Ties | Q4: Win %
L5: 1890s | M5: =COUNTIF(Clean_Data!$B$2:$B$137,L5) -> 10 | N5: =SUMIF(Clean_Data!$B$2:$B$137,L5,Clean_Data!$F$2:$F$137) -> 41 | O5: =SUMIF(Clean_Data!$B$2:$B$137,L5,Clean_Data!$G$2:$G$137) -> 25 | P5: =SUMIF(Clean_Data!$B$2:$B$137,L5,Clean_Data!$H$2:$H$137) -> 4 | Q5: =(N5+0.5*P5)/(N5+O5+P5) -> 0.61428571
L6: 1900s | M6: =COUNTIF(Clean_Data!$B$2:$B$137,L6) -> 10 | N6: =SUMIF(Clean_Data!$B$2:$B$137,L6,Clean_Data!$F$2:$F$137) -> 70 | O6: =SUMIF(Clean_Data!$B$2:$B$137,L6,Clean_Data!$G$2:$G$137) -> 19 | P6: =SUMIF(Clean_Data!$B$2:$B$137,L6,Clean_Data!$H$2:$H$137) -> 4 | Q6: =(N6+0.5*P6)/(N6+O6+P6) -> 0.77419355
L7: 1910s | M7: =COUNTIF(Clean_Data!$B$2:$B$137,L7) -> 10 | N7: =SUMIF(Clean_Data!$B$2:$B$137,L7,Clean_Data!$F$2:$F$137) -> 58 | O7: =SUMIF(Clean_Data!$B$2:$B$137,L7,Clean_Data!$G$2:$G$137) -> 13 | P7: =SUMIF(Clean_Data!$B$2:$B$137,L7,Clean_Data!$H$2:$H$137) -> 6 | Q7: =(N7+0.5*P7)/(N7+O7+P7) -> 0.79220779
L8: 1920s | M8: =COUNTIF(Clean_Data!$B$2:$B$137,L8) -> 10 | N8: =SUMIF(Clean_Data!$B$2:$B$137,L8,Clean_Data!$F$2:$F$137) -> 55 | O8: =SUMIF(Clean_Data!$B$2:$B$137,L8,Clean_Data!$G$2:$G$137) -> 18 | P8: =SUMIF(Clean_Data!$B$2:$B$137,L8,Clean_Data!$H$2:$H$137) -> 9 | Q8: =(N8+0.5*P8)/(N8+O8+P8) -> 0.72560976
L9: 1930s | M9: =COUNTIF(Clean_Data!$B$2:$B$137,L9) -> 10 | N9: =SUMIF(Clean_Data!$B$2:$B$137,L9,Clean_Data!$F$2:$F$137) -> 62 | O9: =SUMIF(Clean_Data!$B$2:$B$137,L9,Clean_Data!$G$2:$G$137) -> 21 | P9: =SUMIF(Clean_Data!$B$2:$B$137,L9,Clean_Data!$H$2:$H$137) -> 8 | Q9: =(N9+0.5*P9)/(N9+O9+P9) -> 0.72527473
L10: 1940s | M10: =COUNTIF(Clean_Data!$B$2:$B$137,L10) -> 10 | N10: =SUMIF(Clean_Data!$B$2:$B$137,L10,Clean_Data!$F$2:$F$137) -> 34 | O10: =SUMIF(Clean_Data!$B$2:$B$137,L10,Clean_Data!$G$2:$G$137) -> 57 | P10: =SUMIF(Clean_Data!$B$2:$B$137,L10,Clean_Data!$H$2:$H$137) -> 0 | Q10: =(N10+0.5*P10)/(N10+O10+P10) -> 0.37362637
L11: 1950s | M11: =COUNTIF(Clean_Data!$B$2:$B$137,L11) -> 10 | N11: =SUMIF(Clean_Data!$B$2:$B$137,L11,Clean_Data!$F$2:$F$137) -> 39 | O11: =SUMIF(Clean_Data!$B$2:$B$137,L11,Clean_Data!$G$2:$G$137) -> 58 | P11: =SUMIF(Clean_Data!$B$2:$B$137,L11,Clean_Data!$H$2:$H$137) -> 3 | Q11: =(N11+0.5*P11)/(N11+O11+P11) -> 0.405
L12: 1960s | M12: =COUNTIF(Clean_Data!$B$2:$B$137,L12) -> 10 | N12: =SUMIF(Clean_Data!$B$2:$B$137,L12,Clean_Data!$F$2:$F$137) -> 75 | O12: =SUMIF(Clean_Data!$B$2:$B$137,L12,Clean_Data!$G$2:$G$137) -> 30 | P12: =SUMIF(Clean_Data!$B$2:$B$137,L12,Clean_Data!$H$2:$H$137) -> 1 | Q12: =(N12+0.5*P12)/(N12+O12+P12) -> 0.71226415
L13: 1970s | M13: =COUNTIF(Clean_Data!$B$2:$B$137,L13) -> 10 | N13: =SUMIF(Clean_Data!$B$2:$B$137,L13,Clean_Data!$F$2:$F$137) -> 98 | O13: =SUMIF(Clean_Data!$B$2:$B$137,L13,Clean_Data!$G$2:$G$137) -> 20 | P13: =SUMIF(Clean_Data!$B$2:$B$137,L13,Clean_Data!$H$2:$H$137) -> 4 | Q13: =(N13+0.5*P13)/(N13+O13+P13) -> 0.81967213
L14: 1980s | M14: =COUNTIF(Clean_Data!$B$2:$B$137,L14) -> 10 | N14: =SUMIF(Clean_Data!$B$2:$B$137,L14,Clean_Data!$F$2:$F$137) -> 103 | O14: =SUMIF(Clean_Data!$B$2:$B$137,L14,Clean_Data!$G$2:$G$137) -> 20 | P14: =SUMIF(Clean_Data!$B$2:$B$137,L14,Clean_Data!$H$2:$H$137) -> 0 | Q14: =(N14+0.5*P14)/(N14+O14+P14) -> 0.83739837
L15: 1990s | M15: =COUNTIF(Clean_Data!$B$2:$B$137,L15) -> 10 | N15: =SUMIF(Clean_Data!$B$2:$B$137,L15,Clean_Data!$F$2:$F$137) -> 108 | O15: =SUMIF(Clean_Data!$B$2:$B$137,L15,Clean_Data!$G$2:$G$137) -> 16 | P15: =SUMIF(Clean_Data!$B$2:$B$137,L15,Clean_Data!$H$2:$H$137) -> 1 | Q15: =(N15+0.5*P15)/(N15+O15+P15) -> 0.868
L16: 2000s | M16: =COUNTIF(Clean_Data!$B$2:$B$137,L16) -> 10 | N16: =SUMIF(Clean_Data!$B$2:$B$137,L16,Clean_Data!$F$2:$F$137) -> 84 | O16: =SUMIF(Clean_Data!$B$2:$B$137,L16,Clean_Data!$G$2:$G$137) -> 44 | P16: =SUMIF(Clean_Data!$B$2:$B$137,L16,Clean_Data!$H$2:$H$137) -> 0 | Q16: =(N16+0.5*P16)/(N16+O16+P16) -> 0.65625
... L18: 2020s | M18: =COUNTIF(Clean_Data!$B$2:$B$137,L18) -> 6 | N18: =SUMIF(Clean_Data!$B$2:$B$137,L18,Clean_Data!$F$2:$F$137) -> 29 | O18: =SUMIF(Clean_Data!$B$2:$B$137,L18,Clean_Data!$G$2:$G$137) -> 41 | P18: =SUMIF(Clean_Data!$B$2:$B$137,L18,Clean_Data!$H$2:$H$137) -> 0 | Q18: =(N18+0.5*P18)/(N18+O18+P18) -> 0.41428571
L19: Note: 2020s = 6 seasons (2020-2025). Ties count as half a win.
A26: Story
A27: The 1990s were the best decade at .868, and the 70s, 80s, and 90s were all above .800. The 1940s were the worst (.374). Every decade since the 1990s has been worse than the one before it, and the 2020s are at .414 so far.

Sheet G3_Coaches
A1: Goal 3: Head Coaches Since 1962
A2: Goal: Compare the win percentage of every head coach since 1962.
L4: Head coach | M4: Seasons | N4: Wins | O4: Losses | P4: Ties | Q4: Win % | R4: Bowl games | S4: Final AP ranked | U4: Chart label
L5: Tom Osborne | M5: =COUNTIF(Clean_Data!$C$2:$C$137,L5) -> 25 | N5: =SUMIF(Clean_Data!$C$2:$C$137,L5,Clean_Data!$F$2:$F$137) -> 255 | O5: =SUMIF(Clean_Data!$C$2:$C$137,L5,Clean_Data!$G$2:$G$137) -> 49 | P5: =SUMIF(Clean_Data!$C$2:$C$137,L5,Clean_Data!$H$2:$H$137) -> 3 | Q5: =(N5+0.5*P5)/(N5+O5+P5) -> 0.83550489 | R5: =COUNTIFS(Clean_Data!$C$2:$C$137,L5,Clean_Data!$R$2:$R$137,"Yes") -> 25 | S5: =COUNTIFS(Clean_Data!$C$2:$C$137,L5,Clean_Data!$X$2:$X$137,"Yes") -> 25 | U5: =L5&" (1973-1997)" -> Tom Osborne (1973-1997)
L6: Bob Devaney | M6: =COUNTIF(Clean_Data!$C$2:$C$137,L6) -> 11 | N6: =SUMIF(Clean_Data!$C$2:$C$137,L6,Clean_Data!$F$2:$F$137) -> 101 | O6: =SUMIF(Clean_Data!$C$2:$C$137,L6,Clean_Data!$G$2:$G$137) -> 20 | P6: =SUMIF(Clean_Data!$C$2:$C$137,L6,Clean_Data!$H$2:$H$137) -> 2 | Q6: =(N6+0.5*P6)/(N6+O6+P6) -> 0.82926829 | R6: =COUNTIFS(Clean_Data!$C$2:$C$137,L6,Clean_Data!$R$2:$R$137,"Yes") -> 9 | S6: =COUNTIFS(Clean_Data!$C$2:$C$137,L6,Clean_Data!$X$2:$X$137,"Yes") -> 8 | U6: =L6&" (1962-1972)" -> Bob Devaney (1962-1972)
L7: Frank Solich | M7: =COUNTIF(Clean_Data!$C$2:$C$137,L7) -> 6 | N7: =SUMIF(Clean_Data!$C$2:$C$137,L7,Clean_Data!$F$2:$F$137) -> 59 | O7: =SUMIF(Clean_Data!$C$2:$C$137,L7,Clean_Data!$G$2:$G$137) -> 19 | P7: =SUMIF(Clean_Data!$C$2:$C$137,L7,Clean_Data!$H$2:$H$137) -> 0 | Q7: =(N7+0.5*P7)/(N7+O7+P7) -> 0.75641026 | R7: =COUNTIFS(Clean_Data!$C$2:$C$137,L7,Clean_Data!$R$2:$R$137,"Yes") -> 6 | S7: =COUNTIFS(Clean_Data!$C$2:$C$137,L7,Clean_Data!$X$2:$X$137,"Yes") -> 5 | U7: =L7&" (1998-2003)" -> Frank Solich (1998-2003)
L8: Bo Pelini | M8: =COUNTIF(Clean_Data!$C$2:$C$137,L8) -> 7 | N8: =SUMIF(Clean_Data!$C$2:$C$137,L8,Clean_Data!$F$2:$F$137) -> 66 | O8: =SUMIF(Clean_Data!$C$2:$C$137,L8,Clean_Data!$G$2:$G$137) -> 28 | P8: =SUMIF(Clean_Data!$C$2:$C$137,L8,Clean_Data!$H$2:$H$137) -> 0 | Q8: =(N8+0.5*P8)/(N8+O8+P8) -> 0.70212766 | R8: =COUNTIFS(Clean_Data!$C$2:$C$137,L8,Clean_Data!$R$2:$R$137,"Yes") -> 7 | S8: =COUNTIFS(Clean_Data!$C$2:$C$137,L8,Clean_Data!$X$2:$X$137,"Yes") -> 4 | U8: =L8&" (2008-2014)" -> Bo Pelini (2008-2014)
L9: Bill Callahan | M9: =COUNTIF(Clean_Data!$C$2:$C$137,L9) -> 4 | N9: =SUMIF(Clean_Data!$C$2:$C$137,L9,Clean_Data!$F$2:$F$137) -> 27 | O9: =SUMIF(Clean_Data!$C$2:$C$137,L9,Clean_Data!$G$2:$G$137) -> 22 | P9: =SUMIF(Clean_Data!$C$2:$C$137,L9,Clean_Data!$H$2:$H$137) -> 0 | Q9: =(N9+0.5*P9)/(N9+O9+P9) -> 0.55102041 | R9: =COUNTIFS(Clean_Data!$C$2:$C$137,L9,Clean_Data!$R$2:$R$137,"Yes") -> 2 | S9: =COUNTIFS(Clean_Data!$C$2:$C$137,L9,Clean_Data!$X$2:$X$137,"Yes") -> 1 | U9: =L9&" (2004-2007)" -> Bill Callahan (2004-2007)
L10: Mike Riley | M10: =COUNTIF(Clean_Data!$C$2:$C$137,L10) -> 3 | N10: =SUMIF(Clean_Data!$C$2:$C$137,L10,Clean_Data!$F$2:$F$137) -> 19 | O10: =SUMIF(Clean_Data!$C$2:$C$137,L10,Clean_Data!$G$2:$G$137) -> 19 | P10: =SUMIF(Clean_Data!$C$2:$C$137,L10,Clean_Data!$H$2:$H$137) -> 0 | Q10: =(N10+0.5*P10)/(N10+O10+P10) -> 0.5 | R10: =COUNTIFS(Clean_Data!$C$2:$C$137,L10,Clean_Data!$R$2:$R$137,"Yes") -> 2 | S10: =COUNTIFS(Clean_Data!$C$2:$C$137,L10,Clean_Data!$X$2:$X$137,"Yes") -> 0 | U10: =L10&" (2015-2017)" -> Mike Riley (2015-2017)
L11: Matt Rhule | M11: =COUNTIF(Clean_Data!$C$2:$C$137,L11) -> 3 | N11: =SUMIF(Clean_Data!$C$2:$C$137,L11,Clean_Data!$F$2:$F$137) -> 19 | O11: =SUMIF(Clean_Data!$C$2:$C$137,L11,Clean_Data!$G$2:$G$137) -> 19 | P11: =SUMIF(Clean_Data!$C$2:$C$137,L11,Clean_Data!$H$2:$H$137) -> 0 | Q11: =(N11+0.5*P11)/(N11+O11+P11) -> 0.5 | R11: =COUNTIFS(Clean_Data!$C$2:$C$137,L11,Clean_Data!$R$2:$R$137,"Yes") -> 2 | S11: =COUNTIFS(Clean_Data!$C$2:$C$137,L11,Clean_Data!$X$2:$X$137,"Yes") -> 0 | U11: =L11&" (2023-2025)" -> Matt Rhule (2023-2025)
L12: Scott Frost | M12: =COUNTIF(Clean_Data!$C$2:$C$137,L12) -> 5 | N12: =SUMIF(Clean_Data!$C$2:$C$137,L12,Clean_Data!$F$2:$F$137) -> 19 | O12: =SUMIF(Clean_Data!$C$2:$C$137,L12,Clean_Data!$G$2:$G$137) -> 37 | P12: =SUMIF(Clean_Data!$C$2:$C$137,L12,Clean_Data!$H$2:$H$137) -> 0 | Q12: =(N12+0.5*P12)/(N12+O12+P12) -> 0.33928571 | R12: =COUNTIFS(Clean_Data!$C$2:$C$137,L12,Clean_Data!$R$2:$R$137,"Yes") -> 0 | S12: =COUNTIFS(Clean_Data!$C$2:$C$137,L12,Clean_Data!$X$2:$X$137,"Yes") -> 0 | U12: =L12&" (2018-2022)" -> Scott Frost (2018-2022)
L13: Coaches since 1962, sorted by win %. Interim coaches credited per source table.
A26: Story
A27: Osborne (.836) and Devaney (.829) are way ahead of everyone else. Osborne went to a bowl and finished ranked in all 25 of his seasons. Every coach since 2015 is at .500 or below, and Scott Frost (.339) is the lowest.

Sheet G4_Eras
A1: Goal 4: Conference Eras
A2: Goal: Compare Nebraska's results in the Big Eight, Big 12, and Big Ten.
L4: Conference era | M4: Seasons | N4: Overall win % | O4: Conference win % | P4: % seasons with bowl | Q4: % seasons final AP ranked
L5: Big Eight (1962-95) | M5: =COUNTIF(Clean_Data!$E$2:$E$137,L5) -> 34 | N5: =(SUMIF(Clean_Data!$E$2:$E$137,L5,Clean_Data!$F$2:$F$137)+0.5*SUMIF(Clean_Data!$E$2:$E$137,L5,Clean_Data!$H$2:$H$137))/SUMIF(Clean_Data!$E$2:$E$137,L5,Clean_Data!$I$2:$I$137) -> 0.8279703 | O5: =(SUMIF(Clean_Data!$E$2:$E$137,L5,Clean_Data!$K$2:$K$137)+0.5*SUMIF(Clean_Data!$E$2:$E$137,L5,Clean_Data!$M$2:$M$137))/(SUMIF(Clean_Data!$E$2:$E$137,L5,Clean_Data!$K$2:$K$137)+SUMIF(Clean_Data!$E$2:$E$137,L5,Clean_Data!$L$2:$L$137)+SUMIF(Clean_Data!$E$2:$E$137,L5,Clean_Data!$M$2:$M$137)) -> 0.84243697 | P5: =COUNTIFS(Clean_Data!$E$2:$E$137,L5,Clean_Data!$R$2:$R$137,"Yes")/M5 -> 0.94117647 | Q5: =COUNTIFS(Clean_Data!$E$2:$E$137,L5,Clean_Data!$X$2:$X$137,"Yes")/M5 -> 0.91176471
L6: Big 12 (1996-2010) | M6: =COUNTIF(Clean_Data!$E$2:$E$137,L6) -> 15 | N6: =(SUMIF(Clean_Data!$E$2:$E$137,L6,Clean_Data!$F$2:$F$137)+0.5*SUMIF(Clean_Data!$E$2:$E$137,L6,Clean_Data!$H$2:$H$137))/SUMIF(Clean_Data!$E$2:$E$137,L6,Clean_Data!$I$2:$I$137) -> 0.71649485 | O6: =(SUMIF(Clean_Data!$E$2:$E$137,L6,Clean_Data!$K$2:$K$137)+0.5*SUMIF(Clean_Data!$E$2:$E$137,L6,Clean_Data!$M$2:$M$137))/(SUMIF(Clean_Data!$E$2:$E$137,L6,Clean_Data!$K$2:$K$137)+SUMIF(Clean_Data!$E$2:$E$137,L6,Clean_Data!$L$2:$L$137)+SUMIF(Clean_Data!$E$2:$E$137,L6,Clean_Data!$M$2:$M$137)) -> 0.675 | P6: =COUNTIFS(Clean_Data!$E$2:$E$137,L6,Clean_Data!$R$2:$R$137,"Yes")/M6 -> 0.86666667 | Q6: =COUNTIFS(Clean_Data!$E$2:$E$137,L6,Clean_Data!$X$2:$X$137,"Yes")/M6 -> 0.66666667
L7: Big Ten (2011-25) | M7: =COUNTIF(Clean_Data!$E$2:$E$137,L7) -> 15 | N7: =(SUMIF(Clean_Data!$E$2:$E$137,L7,Clean_Data!$F$2:$F$137)+0.5*SUMIF(Clean_Data!$E$2:$E$137,L7,Clean_Data!$H$2:$H$137))/SUMIF(Clean_Data!$E$2:$E$137,L7,Clean_Data!$I$2:$I$137) -> 0.50810811 | O7: =(SUMIF(Clean_Data!$E$2:$E$137,L7,Clean_Data!$K$2:$K$137)+0.5*SUMIF(Clean_Data!$E$2:$E$137,L7,Clean_Data!$M$2:$M$137))/(SUMIF(Clean_Data!$E$2:$E$137,L7,Clean_Data!$K$2:$K$137)+SUMIF(Clean_Data!$E$2:$E$137,L7,Clean_Data!$L$2:$L$137)+SUMIF(Clean_Data!$E$2:$E$137,L7,Clean_Data!$M$2:$M$137)) -> 0.44186047 | P7: =COUNTIFS(Clean_Data!$E$2:$E$137,L7,Clean_Data!$R$2:$R$137,"Yes")/M7 -> 0.53333333 | Q7: =COUNTIFS(Clean_Data!$E$2:$E$137,L7,Clean_Data!$X$2:$X$137,"Yes")/M7 -> 0.13333333
A26: Story
A27: Every measure goes down from the Big Eight to the Big 12 to the Big Ten. The biggest drop is in rankings: 91% of Big Eight seasons ended ranked, but only 13% of Big Ten seasons did. The drop started before the Big Ten though, since the team had bad years in 2004 and 2007.

Sheet G5_Bowls
A1: Goal 5: Bowl Games
A2: Goal: Show bowl wins and losses by decade.
L4: Decade | M4: Bowl wins | N4: Bowl losses | O4: Bowl games | P4: Seasons | Q4: % seasons in a bowl
L5: 1940s | M5: =COUNTIFS(Clean_Data!$B$2:$B$137,L5,Clean_Data!$T$2:$T$137,"W") -> 0 | N5: =COUNTIFS(Clean_Data!$B$2:$B$137,L5,Clean_Data!$T$2:$T$137,"L") -> 1 | O5: =M5+N5 -> 1 | P5: =COUNTIF(Clean_Data!$B$2:$B$137,L5) -> 10 | Q5: =O5/P5 -> 0.1
L6: 1950s | M6: =COUNTIFS(Clean_Data!$B$2:$B$137,L6,Clean_Data!$T$2:$T$137,"W") -> 0 | N6: =COUNTIFS(Clean_Data!$B$2:$B$137,L6,Clean_Data!$T$2:$T$137,"L") -> 1 | O6: =M6+N6 -> 1 | P6: =COUNTIF(Clean_Data!$B$2:$B$137,L6) -> 10 | Q6: =O6/P6 -> 0.1
L7: 1960s | M7: =COUNTIFS(Clean_Data!$B$2:$B$137,L7,Clean_Data!$T$2:$T$137,"W") -> 3 | N7: =COUNTIFS(Clean_Data!$B$2:$B$137,L7,Clean_Data!$T$2:$T$137,"L") -> 3 | O7: =M7+N7 -> 6 | P7: =COUNTIF(Clean_Data!$B$2:$B$137,L7) -> 10 | Q7: =O7/P7 -> 0.6
L8: 1970s | M8: =COUNTIFS(Clean_Data!$B$2:$B$137,L8,Clean_Data!$T$2:$T$137,"W") -> 7 | N8: =COUNTIFS(Clean_Data!$B$2:$B$137,L8,Clean_Data!$T$2:$T$137,"L") -> 3 | O8: =M8+N8 -> 10 | P8: =COUNTIF(Clean_Data!$B$2:$B$137,L8) -> 10 | Q8: =O8/P8 -> 1
L9: 1980s | M9: =COUNTIFS(Clean_Data!$B$2:$B$137,L9,Clean_Data!$T$2:$T$137,"W") -> 4 | N9: =COUNTIFS(Clean_Data!$B$2:$B$137,L9,Clean_Data!$T$2:$T$137,"L") -> 6 | O9: =M9+N9 -> 10 | P9: =COUNTIF(Clean_Data!$B$2:$B$137,L9) -> 10 | Q9: =O9/P9 -> 1
L10: 1990s | M10: =COUNTIFS(Clean_Data!$B$2:$B$137,L10,Clean_Data!$T$2:$T$137,"W") -> 5 | N10: =COUNTIFS(Clean_Data!$B$2:$B$137,L10,Clean_Data!$T$2:$T$137,"L") -> 5 | O10: =M10+N10 -> 10 | P10: =COUNTIF(Clean_Data!$B$2:$B$137,L10) -> 10 | Q10: =O10/P10 -> 1
L11: 2000s | M11: =COUNTIFS(Clean_Data!$B$2:$B$137,L11,Clean_Data!$T$2:$T$137,"W") -> 5 | N11: =COUNTIFS(Clean_Data!$B$2:$B$137,L11,Clean_Data!$T$2:$T$137,"L") -> 3 | O11: =M11+N11 -> 8 | P11: =COUNTIF(Clean_Data!$B$2:$B$137,L11) -> 10 | Q11: =O11/P11 -> 0.8
L12: 2010s | M12: =COUNTIFS(Clean_Data!$B$2:$B$137,L12,Clean_Data!$T$2:$T$137,"W") -> 2 | N12: =COUNTIFS(Clean_Data!$B$2:$B$137,L12,Clean_Data!$T$2:$T$137,"L") -> 5 | O12: =M12+N12 -> 7 | P12: =COUNTIF(Clean_Data!$B$2:$B$137,L12) -> 10 | Q12: =O12/P12 -> 0.7
L13: 2020s | M13: =COUNTIFS(Clean_Data!$B$2:$B$137,L13,Clean_Data!$T$2:$T$137,"W") -> 1 | N13: =COUNTIFS(Clean_Data!$B$2:$B$137,L13,Clean_Data!$T$2:$T$137,"L") -> 1 | O13: =M13+N13 -> 2 | P13: =COUNTIF(Clean_Data!$B$2:$B$137,L13) -> 6 | Q13: =O13/P13 -> 0.33333333
L14: Total | M14: =SUM(M5:M13) -> 27 | N14: =SUM(N5:N13) -> 28 | O14: =SUM(O5:O13) -> 55 | P14: =SUM(P5:P13) -> 86
L15: Nebraska's first bowl game was the 1941 Rose Bowl (1940 season).
A26: Story
A27: Nebraska went to 35 bowl games in a row from 1969 to 2003, so the 70s, 80s, and 90s all have 10. The 1970s were the best at 7-3. The all-time bowl record is 27-28, but only 3-5 in the Big Ten. The team didn't go to a bowl from 2017 to 2023.

Sheet G6_Rankings
A1: Goal 6: Final AP Rankings
A2: Goal: Show Nebraska's final AP ranking each season to see when they were a national power.
L4: Season | M4: Final AP rank | O4: Decade | P4: Seasons ranked | Q4: Top-10 finishes
L5: =Clean_Data!A48 -> 1936 | M5: =Clean_Data!V48 -> 9 | O5: 1930s | P5: =COUNTIFS(Clean_Data!$B$2:$B$137,O5,Clean_Data!$X$2:$X$137,"Yes") -> 3 | Q5: =COUNTIFS(Clean_Data!$B$2:$B$137,O5,Clean_Data!$V$2:$V$137,"<=10") -> 1
L6: =Clean_Data!A49 -> 1937 | M6: =Clean_Data!V49 -> 11 | O6: 1940s | P6: =COUNTIFS(Clean_Data!$B$2:$B$137,O6,Clean_Data!$X$2:$X$137,"Yes") -> 1 | Q6: =COUNTIFS(Clean_Data!$B$2:$B$137,O6,Clean_Data!$V$2:$V$137,"<=10") -> 1
L7: =Clean_Data!A51 -> 1939 | M7: =Clean_Data!V51 -> 18 | O7: 1950s | P7: =COUNTIFS(Clean_Data!$B$2:$B$137,O7,Clean_Data!$X$2:$X$137,"Yes") -> 1 | Q7: =COUNTIFS(Clean_Data!$B$2:$B$137,O7,Clean_Data!$V$2:$V$137,"<=10") -> 0
L8: =Clean_Data!A52 -> 1940 | M8: =Clean_Data!V52 -> 7 | O8: 1960s | P8: =COUNTIFS(Clean_Data!$B$2:$B$137,O8,Clean_Data!$X$2:$X$137,"Yes") -> 5 | Q8: =COUNTIFS(Clean_Data!$B$2:$B$137,O8,Clean_Data!$V$2:$V$137,"<=10") -> 4
L9: =Clean_Data!A62 -> 1950 | M9: =Clean_Data!V62 -> 17 | O9: 1970s | P9: =COUNTIFS(Clean_Data!$B$2:$B$137,O9,Clean_Data!$X$2:$X$137,"Yes") -> 10 | Q9: =COUNTIFS(Clean_Data!$B$2:$B$137,O9,Clean_Data!$V$2:$V$137,"<=10") -> 9
L10: =Clean_Data!A75 -> 1963 | M10: =Clean_Data!V75 -> 6 | O10: 1980s | P10: =COUNTIFS(Clean_Data!$B$2:$B$137,O10,Clean_Data!$X$2:$X$137,"Yes") -> 10 | Q10: =COUNTIFS(Clean_Data!$B$2:$B$137,O10,Clean_Data!$V$2:$V$137,"<=10") -> 7
L11: =Clean_Data!A76 -> 1964 | M11: =Clean_Data!V76 -> 6 | O11: 1990s | P11: =COUNTIFS(Clean_Data!$B$2:$B$137,O11,Clean_Data!$X$2:$X$137,"Yes") -> 10 | Q11: =COUNTIFS(Clean_Data!$B$2:$B$137,O11,Clean_Data!$V$2:$V$137,"<=10") -> 6
L12: =Clean_Data!A77 -> 1965 | M12: =Clean_Data!V77 -> 5 | O12: 2000s | P12: =COUNTIFS(Clean_Data!$B$2:$B$137,O12,Clean_Data!$X$2:$X$137,"Yes") -> 5 | Q12: =COUNTIFS(Clean_Data!$B$2:$B$137,O12,Clean_Data!$V$2:$V$137,"<=10") -> 2
L13: =Clean_Data!A78 -> 1966 | M13: =Clean_Data!V78 -> 6 | O13: 2010s | P13: =COUNTIFS(Clean_Data!$B$2:$B$137,O13,Clean_Data!$X$2:$X$137,"Yes") -> 3 | Q13: =COUNTIFS(Clean_Data!$B$2:$B$137,O13,Clean_Data!$V$2:$V$137,"<=10") -> 0
L14: =Clean_Data!A81 -> 1969 | M14: =Clean_Data!V81 -> 11 | O14: 2020s | P14: =COUNTIFS(Clean_Data!$B$2:$B$137,O14,Clean_Data!$X$2:$X$137,"Yes") -> 0 | Q14: =COUNTIFS(Clean_Data!$B$2:$B$137,O14,Clean_Data!$V$2:$V$137,"<=10") -> 0
L15: =Clean_Data!A82 -> 1970 | M15: =Clean_Data!V82 -> 1
L16: =Clean_Data!A83 -> 1971 | M16: =Clean_Data!V83 -> 1
L17: =Clean_Data!A84 -> 1972 | M17: =Clean_Data!V84 -> 4
L18: =Clean_Data!A85 -> 1973 | M18: =Clean_Data!V85 -> 7
L19: =Clean_Data!A86 -> 1974 | M19: =Clean_Data!V86 -> 8
L20: =Clean_Data!A87 -> 1975 | M20: =Clean_Data!V87 -> 9
L21: =Clean_Data!A88 -> 1976 | M21: =Clean_Data!V88 -> 9
L22: =Clean_Data!A89 -> 1977 | M22: =Clean_Data!V89 -> 12
L23: =Clean_Data!A90 -> 1978 | M23: =Clean_Data!V90 -> 8
L24: =Clean_Data!A91 -> 1979 | M24: =Clean_Data!V91 -> 9
L25: =Clean_Data!A92 -> 1980 | M25: =Clean_Data!V92 -> 7
A26: Story | L26: =Clean_Data!A93 -> 1981 | M26: =Clean_Data!V93 -> 11
A27: From 1969 to 2001 Nebraska was ranked every year (33 in a row) and finished #1 four times. After 2001 the dots drop and spread out. The last time they finished ranked was 2012 (#25), so it's been 13 seasons. | L27: =Clean_Data!A94 -> 1982 | M27: =Clean_Data!V94 -> 3
L28: =Clean_Data!A95 -> 1983 | M28: =Clean_Data!V95 -> 2
L29: =Clean_Data!A96 -> 1984 | M29: =Clean_Data!V96 -> 4
L30: =Clean_Data!A97 -> 1985 | M30: =Clean_Data!V97 -> 11
L31: =Clean_Data!A98 -> 1986 | M31: =Clean_Data!V98 -> 5
L32: =Clean_Data!A99 -> 1987 | M32: =Clean_Data!V99 -> 6
L33: =Clean_Data!A100 -> 1988 | M33: =Clean_Data!V100 -> 10
L34: =Clean_Data!A101 -> 1989 | M34: =Clean_Data!V101 -> 11
L35: =Clean_Data!A102 -> 1990 | M35: =Clean_Data!V102 -> 24
L36: =Clean_Data!A103 -> 1991 | M36: =Clean_Data!V103 -> 15
L37: =Clean_Data!A104 -> 1992 | M37: =Clean_Data!V104 -> 14
L38: =Clean_Data!A105 -> 1993 | M38: =Clean_Data!V105 -> 3
L39: =Clean_Data!A106 -> 1994 | M39: =Clean_Data!V106 -> 1
... L46: =Clean_Data!A113 -> 2001 | M46: =Clean_Data!V113 -> 8
L47: =Clean_Data!A115 -> 2003 | M47: =Clean_Data!V115 -> 19
...
